Workbook
Name Abruzzo: GeoListe!$B2:$B5
Name Basilicata: GeoListe!$C2:$C3
Name Calabria: GeoListe!$D2:$D6
Name Campania: GeoListe!$E2:$E6
Name Emilia_Romagna: GeoListe!$F2:$F10
Name Friuli_Venezia_Giulia: GeoListe!$G2:$G5
Name Lazio: GeoListe!$H2:$H6
Name Liguria: GeoListe!$I2:$I5
Name Lombardia: GeoListe!$J2:$J13
Name Marche: GeoListe!$K2:$K6
Name Molise: GeoListe!$L2:$L3
Name p_Agrigento: GeoDropdown!$A$2:$A$44
Name p_Alessandria: GeoDropdown!$B$2:$B$188
Name p_Ancona: GeoDropdown!$C$2:$C$48
Name p_Arezzo: GeoDropdown!$D$2:$D$37
Name p_Ascoli_Piceno: GeoDropdown!$E$2:$E$34
Name p_Asti: GeoDropdown!$F$2:$F$118
Name p_Avellino: GeoDropdown!$G$2:$G$119
Name p_Bari: GeoDropdown!$H$2:$H$42
Name p_Barletta_Andria_Trani: GeoDropdown!$I$2:$I$11
Name p_Belluno: GeoDropdown!$J$2:$J$61
Name p_Benevento: GeoDropdown!$K$2:$K$79
Name p_Bergamo: GeoDropdown!$L$2:$L$244
Name p_Biella: GeoDropdown!$M$2:$M$75
Name p_Bologna: GeoDropdown!$N$2:$N$56
Name p_Bolzano_Bozen: GeoDropdown!$O$2:$O$117
Name p_Brescia: GeoDropdown!$P$2:$P$206
Name p_Brindisi: GeoDropdown!$Q$2:$Q$21
Name p_Cagliari: GeoDropdown!$R$2:$R$18
Name p_Caltanissetta: GeoDropdown!$S$2:$S$23
Name p_Campobasso: GeoDropdown!$T$2:$T$85
Name p_Caserta: GeoDropdown!$U$2:$U$105
Name p_Catania: GeoDropdown!$V$2:$V$59
Name p_Catanzaro: GeoDropdown!$W$2:$W$81
Name p_Chieti: GeoDropdown!$X$2:$X$105
Name p_Como: GeoDropdown!$Y$2:$Y$148
Name p_Cosenza: GeoDropdown!$Z$2:$Z$151
Name p_Cremona: GeoDropdown!$AA$2:$AA$114
Name p_Crotone: GeoDropdown!$AB$2:$AB$28
Name p_Cuneo: GeoDropdown!$AC$2:$AC$248
Name p_Enna: GeoDropdown!$AD$2:$AD$21
Name p_Fermo: GeoDropdown!$AE$2:$AE$41
Name p_Ferrara: GeoDropdown!$AF$2:$AF$22
Name p_Firenze: GeoDropdown!$AG$2:$AG$42
Name p_Foggia: GeoDropdown!$AH$2:$AH$62
Name p_Forli_Cesena: GeoDropdown!$AI$2:$AI$31
Name p_Frosinone: GeoDropdown!$AJ$2:$AJ$92
Name p_Genova: GeoDropdown!$AK$2:$AK$68
Name p_Gorizia: GeoDropdown!$AL$2:$AL$26
Name p_Grosseto: GeoDropdown!$AM$2:$AM$29
Name p_Imperia: GeoDropdown!$AN$2:$AN$67
Name p_Isernia: GeoDropdown!$AO$2:$AO$53
Name p_L_Aquila: GeoDropdown!$AP$2:$AP$109
Name p_La_Spezia: GeoDropdown!$AQ$2:$AQ$33
Name p_Latina: GeoDropdown!$AR$2:$AR$34
Name p_Lecce: GeoDropdown!$AS$2:$AS$97
Name p_Lecco: GeoDropdown!$AT$2:$AT$85
Name p_Livorno: GeoDropdown!$AU$2:$AU$20
Name p_Lodi: GeoDropdown!$AV$2:$AV$61
Name p_Lucca: GeoDropdown!$AW$2:$AW$34

Sheet Istruzioni
A1: Alayan - Template Filiale Pipeline FV
A2: Compilare questo file direttamente su OneDrive / SharePoint. Nessun invio via email.
A4: Nome filiale | B4: Catania
A5: Area filiale | B5: =IF(OR(B4="Lucca",B4="Firenze",B4="Livorno",B4="Parma",B4="Sassuolo",B4="Bologna",B4="Rimini",B4="Perugia",B4="Cagliari",B4="Sassari"),"Centro",IF(OR(B4="Roma Nomentana",B4="Roma Aurelia",B4="Frosinone",B4="Napoli",B4="Salerno",B4="Bari",B4="Cosenza",B4="Catania"),"Sud",IF(OR(B4="Genova",B4="Albenga",B4="Bergamo",B4="Brescia",B4="Cuneo",B4="Lecco",B4="Milano Est",B4="Milano Ovest",B4="Milano Nord",B4="Milano Sud",B4="Sondrio",B4="Torino"),"Nord Ovest",IF(OR(B4="Bolzano",B4="Brunico",B4="Padova",B4="Trento",B4="Treviso",B4="Udine",B4="Venezia",B4="Verona"),"Nord Est","")))) -> Sud
A6: Anno base Gantt | B6: 2026
A7: Cartella consigliata | B7: /Alayan Pipeline FV/Filiali/
A9: Istruzioni operative
A10: 1. Salvare una copia del template nella cartella OneDrive/SharePoint della propria filiale.
A11: 2. Compilare solo le celle di input nel foglio 'Pipeline' (testo blu).
A12: 3. Il foglio 'Gantt' si aggiorna automaticamente dalle date inserite nel foglio 'Pipeline'.
A13: 4. Aggiornare almeno: Cliente, Cod. Cliente, Progetto, Potenziale, MWp, Fase attuale, Stato progetto, date di fase, Ultimo aggiornamento.
A14: 5. Non modificare intestazioni, formule o struttura colonne: il dashboard nazionale legge questo layout.
A15: 6. Per nuovi progetti usare una riga libera nel foglio 'Pipeline'. Le righe sono predisposte fino a 200 progetti.
A19: Legenda colori
A20: Blu | B20: input utente
A21: Nero | B21: formula / calcolo
A22: Grigio / teal | B22: istruzioni o costanti

Sheet Progetti
A1: Pipeline progetti filiale
A2: Compilare una riga per progetto. Le date alimentano il Gantt.
A4: Filiale | B4: Area | C4: Cliente | D4: Cod. Cliente | E4: Progetto | F4: Regione | G4: Provincia | H4: Comune | I4: Potenza MWp | J4: Probabilità | K4: Potenziale | L4: Fatturaro | M4: Stato progetto | N4: Fase attuale | O4: Responsabile Progetto | P4: Data apertura | Q4: Target commissioning | R4: Ultimo aggiornamento | S4: Ritardo (gg) | T4: Stato scadenza | U4: Note | V4: SdF Inizio | W4: SdF Fine | X4: Prog. Inizio | Y4: Prog. Fine | Z4: Aut. Inizio | AA4: Aut. Fine | AB4: Proc. Inizio | AC4: Proc. Fine | AD4: Costr. Inizio | AE4: Costr. Fine | AF4: Comm. Inizio | AG4: Comm. Fine | AH4: Avanzamento %
A5: =Istruzioni!$B$4 -> Catania | B5: =Istruzioni!$B$5 -> Sud | C5: ALTOBRANDO SRL | E5: Altobrando | F5: Sicilia | G5: Catania | H5: Caltagirone | I5: 45 | M5: In pipeline | N5: Autorizzazioni | R5: 46110 | S5: =IF(OR(Q5="",M5="Completato",M5="Perso"),"",MAX(TODAY()-Q5,0)) | T5: =IF(OR(Q5="",M5="Completato",M5="Perso"),"",IF(Q5<TODAY(),"In ritardo",IF(Q5<=TODAY()+30,"In scadenza","On track"))) | U5: VIA approvata | Z5: 46108 | AA5: 46265 | AH5: =IFERROR(VLOOKUP(N5,Liste!$D$4:$E$10,2,FALSE),"") -> 0.45
A6: =Istruzioni!$B$4 -> Catania | B6: =Istruzioni!$B$5 -> Sud | C6: IBERDROLA RENOVABLES ITALIA SPA | E6: Lentini1 | F6: Sicilia | G6: Siracusa | H6: Lentini | I6: 60 | M6: In pipeline | N6: Autorizzazioni | R6: 46110 | S6: =IF(OR(Q6="",M6="Completato",M6="Perso"),"",MAX(TODAY()-Q6,0)) | T6: =IF(OR(Q6="",M6="Completato",M6="Perso"),"",IF(Q6<TODAY(),"In ritardo",IF(Q6<=TODAY()+30,"In scadenza","On track"))) | U6: Progetto anche a Palagonia (CT) | Z6: 46108 | AA6: 46265 | AH6: =IFERROR(VLOOKUP(N6,Liste!$D$4:$E$10,2,FALSE),"") -> 0.45
A7: =Istruzioni!$B$4 -> Catania | B7: =Istruzioni!$B$5 -> Sud | C7: VARNA SOLAR SRL | E7: Varna Solar | F7: Sicilia | G7: Catania | H7: Belpasso | I7: 45 | M7: In pipeline | N7: Autorizzazioni | R7: 46110 | S7: =IF(OR(Q7="",M7="Completato",M7="Perso"),"",MAX(TODAY()-Q7,0)) | T7: =IF(OR(Q7="",M7="Completato",M7="Perso"),"",IF(Q7<TODAY(),"In ritardo",IF(Q7<=TODAY()+30,"In scadenza","On track"))) | U7: VIA approvata | Z7: 46108 | AA7: 46265 | AH7: =IFERROR(VLOOKUP(N7,Liste!$D$4:$E$10,2,FALSE),"") -> 0.45
A8: =Istruzioni!$B$4 -> Catania | B8: =Istruzioni!$B$5 -> Sud | C8: INE ELIOSMENTA SRL | E8: FV Agrivoltaico Buseto | F8: Sicilia | G8: Trapani | H8: Buseto Palizzolo | I8: 27.65 | M8: In pipeline | N8: Autorizzazioni | R8: 46110 | S8: =IF(OR(Q8="",M8="Completato",M8="Perso"),"",MAX(TODAY()-Q8,0)) | T8: =IF(OR(Q8="",M8="Completato",M8="Perso"),"",IF(Q8<TODAY(),"In ritardo",IF(Q8<=TODAY()+30,"In scadenza","On track"))) | U8: VIA approvata, agrivoltaico | Z8: 46108 | AA8: 46265 | AH8: =IFERROR(VLOOKUP(N8,Liste!$D$4:$E$10,2,FALSE),"") -> 0.45
A9: =Istruzioni!$B$4 -> Catania | B9: =Istruzioni!$B$5 -> Sud | C9: ENGIE GRILLO SRL | E9: Grillo | F9: Sicilia | G9: Trapani | H9: Mazara del Vallo | I9: 54 | M9: In pipeline | N9: Autorizzazioni | R9: 46110 | S9: =IF(OR(Q9="",M9="Completato",M9="Perso"),"",MAX(TODAY()-Q9,0)) | T9: =IF(OR(Q9="",M9="Completato",M9="Perso"),"",IF(Q9<TODAY(),"In ritardo",IF(Q9<=TODAY()+30,"In scadenza","On track"))) | U9: Progetto anche a Marsala (TP) | Z9: 46108 | AA9: 46265 | AH9: =IFERROR(VLOOKUP(N9,Liste!$D$4:$E$10,2,FALSE),"") -> 0.45
A10: =Istruzioni!$B$4 -> Catania | B10: =Istruzioni!$B$5 -> Sud | C10: ARYA SOLAR SRL | E10: Arya Mazara | F10: Sicilia | G10: Trapani | H10: Mazara del Vallo | I10: 42.3 | M10: In pipeline | N10: Autorizzazioni | R10: 46030 | S10: =IF(OR(Q10="",M10="Completato",M10="Perso"),"",MAX(TODAY()-Q10,0)) | T10: =IF(OR(Q10="",M10="Completato",M10="Perso"),"",IF(Q10<TODAY(),"In ritardo",IF(Q10<=TODAY()+30,"In scadenza","On track"))) | U10: VIA approvata | Z10: 46030 | AA10: 46203 | AH10: =IFERROR(VLOOKUP(N10,Liste!$D$4:$E$10,2,FALSE),"") -> 0.45
A11: =Istruzioni!$B$4 -> Catania | B11: =Istruzioni!$B$5 -> Sud | C11: PIROIDE SRL | E11: Progetto Piana degli Albanesi | F11: Sicilia | G11: Palermo | H11: Piana degli Albanesi | I11: 85.1 | M11: In pipeline | N11: Autorizzazioni | R11: 46038 | S11: =IF(OR(Q11="",M11="Completato",M11="Perso"),"",MAX(TODAY()-Q11,0)) | T11: =IF(OR(Q11="",M11="Completato",M11="Perso"),"",IF(Q11<TODAY(),"In ritardo",IF(Q11<=TODAY()+30,"In scadenza","On track"))) | U11: Progetto anche a Monreale (PA) | Z11: 46038 | AA11: 46203 | AH11: =IFERROR(VLOOKUP(N11,Liste!$D$4:$E$10,2,FALSE),"") -> 0.45
A12: =Istruzioni!$B$4 -> Catania | B12: =Istruzioni!$B$5 -> Sud | C12: 11PIU' ENERGIA SRL | E12: Favara 2 | F12: Sicilia | G12: Agrigento | H12: Favara | I12: 65.1 | M12: In pipeline | N12: Autorizzazioni | R12: 46055 | S12: =IF(OR(Q12="",M12="Completato",M12="Perso"),"",MAX(TODAY()-Q12,0)) | T12: =IF(OR(Q12="",M12="Completato",M12="Perso"),"",IF(Q12<TODAY(),"In ritardo",IF(Q12<=TODAY()+30,"In scadenza","On track"))) | U12: Agrivoltaico | Z12: 46055 | AA12: 46234 | AH12: =IFERROR(VLOOKUP(N12,Liste!$D$4:$E$10,2,FALSE),"") -> 0.45
A13: =Istruzioni!$B$4 -> Catania | B13: =Istruzioni!$B$5 -> Sud | C13: NDTHREE SRL | E13: Pecciapertosa | F13: Sicilia | G13: Palermo | H13: Castronovo di Sicilia | I13: 22.57 | M13: In pipeline | N13: Autorizzazioni | R13: 46078 | S13: =IF(OR(Q13="",M13="Completato",M13="Perso"),"",MAX(TODAY()-Q13,0)) | T13: =IF(OR(Q13="",M13="Completato",M13="Perso"),"",IF(Q13<TODAY(),"In ritardo",IF(Q13<=TODAY()+30,"In scadenza","On track"))) | U13: Progetto anche a Lercara Friddi (PA) | Z13: 46078 | AA13: 46234 | AH13: =IFERROR(VLOOKUP(N13,Liste!$D$4:$E$10,2,FALSE),"") -> 0.45
A14: =Istruzioni!$B$4 -> Catania | B14: =Istruzioni!$B$5 -> Sud | C14: IBVI 5 SRL | E14: Castel di Iudica II | F14: Sicilia | G14: Catania | H14: Castel di Iudica | I14: 231.6 | M14: In pipeline | N14: Autorizzazioni | R14: 45923 | S14: =IF(OR(Q14="",M14="Completato",M14="Perso"),"",MAX(TODAY()-Q14,0)) | T14: =IF(OR(Q14="",M14="Completato",M14="Perso"),"",IF(Q14<TODAY(),"In ritardo",IF(Q14<=TODAY()+30,"In scadenza","On track"))) | U14: Progetto anche a Ramacca (CT) | Z14: 45923 | AA14: 46142 | AH14: =IFERROR(VLOOKUP(N14,Liste!$D$4:$E$10,2,FALSE),"") -> 0.45
A15: =Istruzioni!$B$4 -> Catania | B15: =Istruzioni!$B$5 -> Sud | C15: IBVI 22 SRL | E15: Mineo | F15: Sicilia | G15: Enna | H15: Aidone | I15: 263 | M15: In pipeline | N15: Autorizzazioni | R15: 46092 | S15: =IF(OR(Q15="",M15="Completato",M15="Perso"),"",MAX(TODAY()-Q15,0)) | T15: =IF(OR(Q15="",M15="Completato",M15="Perso"),"",IF(Q15<TODAY(),"In ritardo",IF(Q15<=TODAY()+30,"In scadenza","On track"))) | U15: Progetto anche a Mineo e Ramacca (CT) | Z15: 46092 | AA15: 46265 | AH15: =IFERROR(VLOOKUP(N15,Liste!$D$4:$E$10,2,FALSE),"") -> 0.45
A16: =Istruzioni!$B$4 -> Catania | B16: =Istruzioni!$B$5 -> Sud | C16: ENNA 1 PV SRL | E16: Enna 1 | F16: Sicilia | G16: Enna | H16: Enna | I16: 45 | M16: In pipeline | N16: Autorizzazioni | R16: 46086 | S16: =IF(OR(Q16="",M16="Completato",M16="Perso"),"",MAX(TODAY()-Q16,0)) | T16: =IF(OR(Q16="",M16="Completato",M16="Perso"),"",IF(Q16<TODAY(),"In ritardo",IF(Q16<=TODAY()+30,"In scadenza","On track"))) | U16: Agrivoltaico | Z16: 46086 | AA16: 46265 | AH16: =IFERROR(VLOOKUP(N16,Liste!$D$4:$E$10,2,FALSE),"") -> 0.45
... A22: =Istruzioni!$B$4 -> Catania | B22: =Istruzioni!$B$5 -> Sud | C22: CVA EOS SRL | E22: AGV Gatto Corvino | F22: Sicilia | G22: Ragusa | H22: Ragusa | I22: 90.6 | M22: In pipeline | N22: Autorizzazioni | R22: 46114 | S22: =IF(OR(Q22="",M22="Completato",M22="Perso"),"",MAX(TODAY()-Q22,0)) | T22: =IF(OR(Q22="",M22="Completato",M22="Perso"),"",IF(Q22<TODAY(),"In ritardo",IF(Q22<=TODAY()+30,"In scadenza","On track"))) | U22: Agrivoltaico, VIA approvata | Z22: 46114 | AA22: 46295 | AH22: =IFERROR(VLOOKUP(N22,Liste!$D$4:$E$10,2,FALSE),"") -> 0.45
A23: =Istruzioni!$B$4 -> Catania | B23: =Istruzioni!$B$5 -> Sud | C23: PERIDOT SOLAR (ITALY) SRL | E23: PV Monreale e Gibellina | F23: Sicilia | G23: Palermo | H23: Monreale | I23: 137 | M23: In pipeline | N23: Procurement | R23: 46120 | S23: =IF(OR(Q23="",M23="Completato",M23="Perso"),"",MAX(TODAY()-Q23,0)) | T23: =IF(OR(Q23="",M23="Completato",M23="Perso"),"",IF(Q23<TODAY(),"In ritardo",IF(Q23<=TODAY()+30,"In scadenza","On track"))) | U23: Progetto anche a Gibellina(TP) | AB23: 46113 | AC23: 46142 | AH23: =IFERROR(VLOOKUP(N23,Liste!$D$4:$E$10,2,FALSE),"") -> 0.6
A24: =Istruzioni!$B$4 -> Catania | B24: =Istruzioni!$B$5 -> Sud | C24: CCE ITALIA | E24: Smart Island Pantelleria | F24: Sicilia | G24: Trapani | H24: Pantelleria | I24: 0.93 | M24: Attivo | N24: Costruzione | R24: 46125 | S24: =IF(OR(Q24="",M24="Completato",M24="Perso"),"",MAX(TODAY()-Q24,0)) | T24: =IF(OR(Q24="",M24="Completato",M24="Perso"),"",IF(Q24<TODAY(),"In ritardo",IF(Q24<=TODAY()+30,"In scadenza","On track"))) | U24: Lavori in zona Arenella | AD24: 46118 | AE24: 46203 | AH24: =IFERROR(VLOOKUP(N24,Liste!$D$4:$E$10,2,FALSE),"") -> 0.85
A25: =Istruzioni!$B$4 -> Catania | B25: =Istruzioni!$B$5 -> Sud | C25: CAPOBIANCO SRL | E25: Capobianco | F25: Sicilia | G25: Enna | H25: Assoro | I25: 250 | M25: In pipeline | N25: Autorizzazioni | R25: 46125 | S25: =IF(OR(Q25="",M25="Completato",M25="Perso"),"",MAX(TODAY()-Q25,0)) | T25: =IF(OR(Q25="",M25="Completato",M25="Perso"),"",IF(Q25<TODAY(),"In ritardo",IF(Q25<=TODAY()+30,"In scadenza","On track"))) | U25: Progetto anche a Enna e Raddusa (CT) | Z25: 46125 | AA25: 46295 | AH25: =IFERROR(VLOOKUP(N25,Liste!$D$4:$E$10,2,FALSE),"") -> 0.45
A26: =Istruzioni!$B$4 -> Catania | B26: =Istruzioni!$B$5 -> Sud | C26: EDPR SICILIA PV SRL | E26: Zaffarana 38 | F26: Sicilia | G26: Trapani | H26: Trapani | I26: 38.3 | M26: In pipeline | N26: Autorizzazioni | R26: 46125 | S26: =IF(OR(Q26="",M26="Completato",M26="Perso"),"",MAX(TODAY()-Q26,0)) | T26: =IF(OR(Q26="",M26="Completato",M26="Perso"),"",IF(Q26<TODAY(),"In ritardo",IF(Q26<=TODAY()+30,"In scadenza","On track"))) | U26: PUA approvato, agrivoltaico | Z26: 46125 | AA26: 46295 | AH26: =IFERROR(VLOOKUP(N26,Liste!$D$4:$E$10,2,FALSE),"") -> 0.45
A27: =Istruzioni!$B$4 -> Catania | B27: =Istruzioni!$B$5 -> Sud | C27: RENANTIS ITALIA SRL | E27: Biddine | F27: Sicilia | G27: Ragusa | H27: Acate | I27: 35 | M27: In pipeline | N27: Autorizzazioni | R27: 46129 | S27: =IF(OR(Q27="",M27="Completato",M27="Perso"),"",MAX(TODAY()-Q27,0)) | T27: =IF(OR(Q27="",M27="Completato",M27="Perso"),"",IF(Q27<TODAY(),"In ritardo",IF(Q27<=TODAY()+30,"In scadenza","On track"))) | U27: VIA approvata | Z27: 46129 | AA27: 46325 | AH27: =IFERROR(VLOOKUP(N27,Liste!$D$4:$E$10,2,FALSE),"") -> 0.45
A28: =Istruzioni!$B$4 -> Catania | B28: =Istruzioni!$B$5 -> Sud | S28: =IF(OR(Q28="",M28="Completato",M28="Perso"),"",MAX(TODAY()-Q28,0)) | T28: =IF(OR(Q28="",M28="Completato",M28="Perso"),"",IF(Q28<TODAY(),"In ritardo",IF(Q28<=TODAY()+30,"In scadenza","On track"))) | AH28: =IFERROR(VLOOKUP(N28,Liste!$D$4:$E$10,2,FALSE),"")
A29: =Istruzioni!$B$4 -> Catania | B29: =Istruzioni!$B$5 -> Sud | S29: =IF(OR(Q29="",M29="Completato",M29="Perso"),"",MAX(TODAY()-Q29,0)) | T29: =IF(OR(Q29="",M29="Completato",M29="Perso"),"",IF(Q29<TODAY(),"In ritardo",IF(Q29<=TODAY()+30,"In scadenza","On track"))) | AH29: =IFERROR(VLOOKUP(N29,Liste!$D$4:$E$10,2,FALSE),"")
A30: =Istruzioni!$B$4 -> Catania | B30: =Istruzioni!$B$5 -> Sud | S30: =IF(OR(Q30="",M30="Completato",M30="Perso"),"",MAX(TODAY()-Q30,0)) | T30: =IF(OR(Q30="",M30="Completato",M30="Perso"),"",IF(Q30<TODAY(),"In ritardo",IF(Q30<=TODAY()+30,"In scadenza","On track"))) | AH30: =IFERROR(VLOOKUP(N30,Liste!$D$4:$E$10,2,FALSE),"")
A31: =Istruzioni!$B$4 -> Catania | B31: =Istruzioni!$B$5 -> Sud | S31: =IF(OR(Q31="",M31="Completato",M31="Perso"),"",MAX(TODAY()-Q31,0)) | T31: =IF(OR(Q31="",M31="Completato",M31="Perso"),"",IF(Q31<TODAY(),"In ritardo",IF(Q31<=TODAY()+30,"In scadenza","On track"))) | AH31: =IFERROR(VLOOKUP(N31,Liste!$D$4:$E$10,2,FALSE),"")
A32: =Istruzioni!$B$4 -> Catania | B32: =Istruzioni!$B$5 -> Sud | S32: =IF(OR(Q32="",M32="Completato",M32="Perso"),"",MAX(TODAY()-Q32,0)) | T32: =IF(OR(Q32="",M32="Completato",M32="Perso"),"",IF(Q32<TODAY(),"In ritardo",IF(Q32<=TODAY()+30,"In scadenza","On track"))) | AH32: =IFERROR(VLOOKUP(N32,Liste!$D$4:$E$10,2,FALSE),"")
A33: =Istruzioni!$B$4 -> Catania | B33: =Istruzioni!$B$5 -> Sud | S33: =IF(OR(Q33="",M33="Completato",M33="Perso"),"",MAX(TODAY()-Q33,0)) | T33: =IF(OR(Q33="",M33="Completato",M33="Perso"),"",IF(Q33<TODAY(),"In ritardo",IF(Q33<=TODAY()+30,"In scadenza","On track"))) | AH33: =IFERROR(VLOOKUP(N33,Liste!$D$4:$E$10,2,FALSE),"")
A34: =Istruzioni!$B$4 -> Catania | B34: =Istruzioni!$B$5 -> Sud | S34: =IF(OR(Q34="",M34="Completato",M34="Perso"),"",MAX(TODAY()-Q34,0)) | T34: =IF(OR(Q34="",M34="Completato",M34="Perso"),"",IF(Q34<TODAY(),"In ritardo",IF(Q34<=TODAY()+30,"In scadenza","On track"))) | AH34: =IFERROR(VLOOKUP(N34,Liste!$D$4:$E$10,2,FALSE),"")
A35: =Istruzioni!$B$4 -> Catania | B35: =Istruzioni!$B$5 -> Sud | S35: =IF(OR(Q35="",M35="Completato",M35="Perso"),"",MAX(TODAY()-Q35,0)) | T35: =IF(OR(Q35="",M35="Completato",M35="Perso"),"",IF(Q35<TODAY(),"In ritardo",IF(Q35<=TODAY()+30,"In scadenza","On track"))) | AH35: =IFERROR(VLOOKUP(N35,Liste!$D$4:$E$10,2,FALSE),"")
A36: =Istruzioni!$B$4 -> Catania | B36: =Istruzioni!$B$5 -> Sud | S36: =IF(OR(Q36="",M36="Completato",M36="Perso"),"",MAX(TODAY()-Q36,0)) | T36: =IF(OR(Q36="",M36="Completato",M36="Perso"),"",IF(Q36<TODAY(),"In ritardo",IF(Q36<=TODAY()+30,"In scadenza","On track"))) | AH36: =IFERROR(VLOOKUP(N36,Liste!$D$4:$E$10,2,FALSE),"")
A37: =Istruzioni!$B$4 -> Catania | B37: =Istruzioni!$B$5 -> Sud | S37: =IF(OR(Q37="",M37="Completato",M37="Perso"),"",MAX(TODAY()-Q37,0)) | T37: =IF(OR(Q37="",M37="Completato",M37="Perso"),"",IF(Q37<TODAY(),"In ritardo",IF(Q37<=TODAY()+30,"In scadenza","On track"))) | AH37: =IFERROR(VLOOKUP(N37,Liste!$D$4:$E$10,2,FALSE),"")
A38: =Istruzioni!$B$4 -> Catania | B38: =Istruzioni!$B$5 -> Sud | S38: =IF(OR(Q38="",M38="Completato",M38="Perso"),"",MAX(TODAY()-Q38,0)) | T38: =IF(OR(Q38="",M38="Completato",M38="Perso"),"",IF(Q38<TODAY(),"In ritardo",IF(Q38<=TODAY()+30,"In scadenza","On track"))) | AH38: =IFERROR(VLOOKUP(N38,Liste!$D$4:$E$10,2,FALSE),"")
A39: =Istruzioni!$B$4 -> Catania | B39: =Istruzioni!$B$5 -> Sud | S39: =IF(OR(Q39="",M39="Completato",M39="Perso"),"",MAX(TODAY()-Q39,0)) | T39: =IF(OR(Q39="",M39="Completato",M39="Perso"),"",IF(Q39<TODAY(),"In ritardo",IF(Q39<=TODAY()+30,"In scadenza","On track"))) | AH39: =IFERROR(VLOOKUP(N39,Liste!$D$4:$E$10,2,FALSE),"")
... A204: =Istruzioni!$B$4 -> Catania | B204: =Istruzioni!$B$5 -> Sud | S204: =IF(OR(Q204="",M204="Completato",M204="Perso"),"",MAX(TODAY()-Q204,0)) | T204: =IF(OR(Q204="",M204="Completato",M204="Perso"),"",IF(Q204<TODAY(),"In ritardo",IF(Q204<=TODAY()+30,"In scadenza","On track"))) | AH204: =IFERROR(VLOOKUP(N204,Liste!$D$4:$E$10,2,FALSE),"")

Sheet Liste
A1: Liste e mapping
A3: Stato progetto | B3: Albenga | D3: Fase | E3: Avanzamento | G3: Stato scadenza | J3: Legenda Gantt
A4: In pipeline | B4: Bari | D4: Studio di fattibilità | E4: 0.1 | G4: On track | J4: Studio di fattibilità
A5: Attivo | B5: Bergamo | D5: Progettazione | E5: 0.25 | G5: In scadenza | J5: Progettazione
A6: In pausa | B6: Bologna | D6: Autorizzazioni | E6: 0.45 | G6: In ritardo | J6: Autorizzazioni
A7: Completato | B7: Bolzano | D7: Procurement | E7: 0.6 | J7: Procurement
A8: Perso | B8: Brescia | D8: Costruzione | E8: 0.85 | J8: Costruzione
B9: Brunico | D9: Commissioning | E9: 0.95 | J9: Commissioning
B10: Cagliari | D10: Operativo | E10: 1
B11: Catania
B12: Cosenza
B13: Cuneo
B14: Firenze
B15: Frosinone
B16: Genova
B17: Lecco
B18: Livorno
B19: Lucca
B20: Milano Est
B21: Milano Nord
B22: Milano Ovest
... B40: Verona

Sheet Gantt Chart
A1: Gantt chart progetti filiale
A2: Barre colorate per fase. Le date arrivano dal foglio 'Pipeline'.
A3: Nome filiale | C3: =Istruzioni!$B$4 -> Catania | D3: Anno base | E3: =Istruzioni!$B$6 -> 2026
A6: Filiale | B6: Area | C6: Cliente | D6: Cod. Cliente | E6: Progetto | F6: Potenziale | G6: Fatturato | H6: Fase attuale | I6: Stato | J6: MWp | K6: Target COD | L6: Ultimo aggiornamento | M6: SDF I | N6: SDF F | O6: PROG I | P6: PROG F | Q6: AUT I | R6: AUT F | S6: PROC I | T6: PROC F | U6: COSTR I | V6: COSTR F | W6: COMM I | X6: COMM F | Y6: =DATE($E$3,1,1) -> 46023 | Z6: =DATE($E$3,2,1) -> 46054 | AA6: =DATE($E$3,3,1) -> 46082 | AB6: =DATE($E$3,4,1) -> 46113 | AC6: =DATE($E$3,5,1) -> 46143 | AD6: =DATE($E$3,6,1) -> 46174 | AE6: =DATE($E$3,7,1) -> 46204 | AF6: =DATE($E$3,8,1) -> 46235 | AG6: =DATE($E$3,9,1) -> 46266 | AH6: =DATE($E$3,10,1) -> 46296 | AI6: =DATE($E$3,11,1) -> 46327 | AJ6: =DATE($E$3,12,1) -> 46357 | AK6: =DATE($E$3,13,1) -> 46388 | AL6: =DATE($E$3,14,1) -> 46419 | AM6: =DATE($E$3,15,1) -> 46447 | AN6: =DATE($E$3,16,1) -> 46478 | AO6: =DATE($E$3,17,1) -> 46508 | AP6: =DATE($E$3,18,1) -> 46539 | AQ6: =DATE($E$3,19,1) -> 46569 | AR6: =DATE($E$3,20,1) -> 46600 | AS6: =DATE($E$3,21,1) -> 46631 | AT6: =DATE($E$3,22,1) -> 46661 | AU6: =DATE($E$3,23,1) -> 46692 | AV6: =DATE($E$3,24,1) -> 46722 | AW6: =DATE($E$3,25,1) -> 46753 | AX6: =DATE($E$3,26,1) -> 46784 | AY6: =DATE($E$3,27,1) -> 46813 | AZ6: =DATE($E$3,28,1) -> 46844 | BA6: =DATE($E$3,29,1) -> 46874 | BB6: =DATE($E$3,30,1) -> 46905 | BC6: =DATE($E$3,31,1) -> 46935 | BD6: =DATE($E$3,32,1) -> 46966 | BE6: =DATE($E$3,33,1) -> 46997 | BF6: =DATE($E$3,34,1) -> 47027 | BG6: =DATE($E$3,35,1) -> 47058 | BH6: =DATE($E$3,36,1) -> 47088 | BI6: =DATE($E$3,37,1) -> 47119 | BJ6: =DATE($E$3,38,1) -> 47150 | BK6: =DATE($E$3,39,1) -> 47178 | BL6: =DATE($E$3,40,1) -> 47209 | BM6: =DATE($E$3,41,1) -> 47239 | BN6: =DATE($E$3,42,1) -> 47270 | BO6: =DATE($E$3,43,1) -> 47300 | BP6: =DATE($E$3,44,1) -> 47331 | BQ6: =DATE($E$3,45,1) -> 47362 | BR6: =DATE($E$3,46,1) -> 47392 | BS6: =DATE($E$3,47,1) -> 47423 | BT6: =DATE($E$3,48,1) -> 47453 | BU6: =DATE($E$3,49,1) -> 47484 | BV6: =DATE($E$3,50,1) -> 47515 | BW6: =DATE($E$3,51,1) -> 47543 | BX6: =DATE($E$3,52,1) -> 47574 | BY6: =DATE($E$3,53,1) -> 47604 | BZ6: =DATE($E$3,54,1) -> 47635 | CA6: =DATE($E$3,55,1) -> 47665 | CB6: =DATE($E$3,56,1) -> 47696 | CC6: =DATE($E$3,57,1) -> 47727 | CD6: =DATE($E$3,58,1) -> 47757 | CE6: =DATE($E$3,59,1) -> 47788 | CF6: =DATE($E$3,60,1) -> 47818
A7: =IF(Progetti!E5="","",Progetti!A5) -> Catania | B7: =IF(Progetti!F5="","",Progetti!B5) -> Sud | C7: =IF(Progetti!E5="","",Progetti!C5) -> ALTOBRANDO SRL | D7: =IF(Progetti!F5="","",Progetti!D5) -> 0 | E7: =IF(Progetti!E5="","",Progetti!E5) -> Altobrando | F7: =IF(Progetti!K5="","",Progetti!K5) | G7: =IF(Progetti!L5="","",Progetti!L5) | H7: =IF(Progetti!E5="","",Progetti!N5) -> Autorizzazioni | I7: =IF(Progetti!E5="","",Progetti!M5) -> In pipeline | J7: =IF(Progetti!E5="","",Progetti!I5) -> 45 | K7: =IF(OR(Progetti!E5="",Progetti!Q5=""),"",Progetti!Q5) | L7: =IF(OR(Progetti!E5="",Progetti!R5=""),"",Progetti!R5) -> 46110 | M7: =IF(OR(Progetti!E5="",Progetti!V5=""),"",Progetti!V5) | N7: =IF(OR(Progetti!E5="",Progetti!W5=""),"",Progetti!W5) | O7: =IF(OR(Progetti!E5="",Progetti!X5=""),"",Progetti!X5) | P7: =IF(OR(Progetti!E5="",Progetti!Y5=""),"",Progetti!Y5) | Q7: =IF(OR(Progetti!E5="",Progetti!Z5=""),"",Progetti!Z5) -> 46108 | R7: =IF(OR(Progetti!E5="",Progetti!AA5=""),"",Progetti!AA5) -> 46265 | S7: =IF(OR(Progetti!E5="",Progetti!AB5=""),"",Progetti!AB5) | T7: =IF(OR(Progetti!E5="",Progetti!AC5=""),"",Progetti!AC5) | U7: =IF(OR(Progetti!E5="",Progetti!AD5=""),"",Progetti!AD5) | V7: =IF(OR(Progetti!E5="",Progetti!AE5=""),"",Progetti!AE5) | W7: =IF(OR(Progetti!E5="",Progetti!AF5=""),"",Progetti!AF5) | X7: =IF(OR(Progetti!E5="",Progetti!AG5=""),"",Progetti!AG5)
A8: =IF(Progetti!E6="","",Progetti!A6) -> Catania | B8: =IF(Progetti!F6="","",Progetti!B6) -> Sud | C8: =IF(Progetti!E6="","",Progetti!C6) -> IBERDROLA RENOVABLES ITALIA SPA | D8: =IF(Progetti!F6="","",Progetti!D6) -> 0 | E8: =IF(Progetti!E6="","",Progetti!E6) -> Lentini1 | F8: =IF(Progetti!K6="","",Progetti!K6) | G8: =IF(Progetti!L6="","",Progetti!L6) | H8: =IF(Progetti!E6="","",Progetti!N6) -> Autorizzazioni | I8: =IF(Progetti!E6="","",Progetti!M6) -> In pipeline | J8: =IF(Progetti!E6="","",Progetti!I6) -> 60 | K8: =IF(OR(Progetti!E6="",Progetti!Q6=""),"",Progetti!Q6) | L8: =IF(OR(Progetti!E6="",Progetti!R6=""),"",Progetti!R6) -> 46110 | M8: =IF(OR(Progetti!E6="",Progetti!V6=""),"",Progetti!V6) | N8: =IF(OR(Progetti!E6="",Progetti!W6=""),"",Progetti!W6) | O8: =IF(OR(Progetti!E6="",Progetti!X6=""),"",Progetti!X6) | P8: =IF(OR(Progetti!E6="",Progetti!Y6=""),"",Progetti!Y6) | Q8: =IF(OR(Progetti!E6="",Progetti!Z6=""),"",Progetti!Z6) -> 46108 | R8: =IF(OR(Progetti!E6="",Progetti!AA6=""),"",Progetti!AA6) -> 46265 | S8: =IF(OR(Progetti!E6="",Progetti!AB6=""),"",Progetti!AB6) | T8: =IF(OR(Progetti!E6="",Progetti!AC6=""),"",Progetti!AC6) | U8: =IF(OR(Progetti!E6="",Progetti!AD6=""),"",Progetti!AD6) | V8: =IF(OR(Progetti!E6="",Progetti!AE6=""),"",Progetti!AE6) | W8: =IF(OR(Progetti!E6="",Progetti!AF6=""),"",Progetti!AF6) | X8: =IF(OR(Progetti!E6="",Progetti!AG6=""),"",Progetti!AG6)
A9: =IF(Progetti!E7="","",Progetti!A7) -> Catania | B9: =IF(Progetti!F7="","",Progetti!B7) -> Sud | C9: =IF(Progetti!E7="","",Progetti!C7) -> VARNA SOLAR SRL | D9: =IF(Progetti!F7="","",Progetti!D7) -> 0 | E9: =IF(Progetti!E7="","",Progetti!E7) -> Varna Solar | F9: =IF(Progetti!K7="","",Progetti!K7) | G9: =IF(Progetti!L7="","",Progetti!L7) | H9: =IF(Progetti!E7="","",Progetti!N7) -> Autorizzazioni | I9: =IF(Progetti!E7="","",Progetti!M7) -> In pipeline | J9: =IF(Progetti!E7="","",Progetti!I7) -> 45 | K9: =IF(OR(Progetti!E7="",Progetti!Q7=""),"",Progetti!Q7) | L9: =IF(OR(Progetti!E7="",Progetti!R7=""),"",Progetti!R7) -> 46110 | M9: =IF(OR(Progetti!E7="",Progetti!V7=""),"",Progetti!V7) | N9: =IF(OR(Progetti!E7="",Progetti!W7=""),"",Progetti!W7) | O9: =IF(OR(Progetti!E7="",Progetti!X7=""),"",Progetti!X7) | P9: =IF(OR(Progetti!E7="",Progetti!Y7=""),"",Progetti!Y7) | Q9: =IF(OR(Progetti!E7="",Progetti!Z7=""),"",Progetti!Z7) -> 46108 | R9: =IF(OR(Progetti!E7="",Progetti!AA7=""),"",Progetti!AA7) -> 46265 | S9: =IF(OR(Progetti!E7="",Progetti!AB7=""),"",Progetti!AB7) | T9: =IF(OR(Progetti!E7="",Progetti!AC7=""),"",Progetti!AC7) | U9: =IF(OR(Progetti!E7="",Progetti!AD7=""),"",Progetti!AD7) | V9: =IF(OR(Progetti!E7="",Progetti!AE7=""),"",Progetti!AE7) | W9: =IF(OR(Progetti!E7="",Progetti!AF7=""),"",Progetti!AF7) | X9: =IF(OR(Progetti!E7="",Progetti!AG7=""),"",Progetti!AG7)
A10: =IF(Progetti!E8="","",Progetti!A8) -> Catania | B10: =IF(Progetti!F8="","",Progetti!B8) -> Sud | C10: =IF(Progetti!E8="","",Progetti!C8) -> INE ELIOSMENTA SRL | D10: =IF(Progetti!F8="","",Progetti!D8) -> 0 | E10: =IF(Progetti!E8="","",Progetti!E8) -> FV Agrivoltaico Buseto | F10: =IF(Progetti!K8="","",Progetti!K8) | G10: =IF(Progetti!L8="","",Progetti!L8) | H10: =IF(Progetti!E8="","",Progetti!N8) -> Autorizzazioni | I10: =IF(Progetti!E8="","",Progetti!M8) -> In pipeline | J10: =IF(Progetti!E8="","",Progetti!I8) -> 27.65 | K10: =IF(OR(Progetti!E8="",Progetti!Q8=""),"",Progetti!Q8) | L10: =IF(OR(Progetti!E8="",Progetti!R8=""),"",Progetti!R8) -> 46110 | M10: =IF(OR(Progetti!E8="",Progetti!V8=""),"",Progetti!V8) | N10: =IF(OR(Progetti!E8="",Progetti!W8=""),"",Progetti!W8) | O10: =IF(OR(Progetti!E8="",Progetti!X8=""),"",Progetti!X8) | P10: =IF(OR(Progetti!E8="",Progetti!Y8=""),"",Progetti!Y8) | Q10: =IF(OR(Progetti!E8="",Progetti!Z8=""),"",Progetti!Z8) -> 46108 | R10: =IF(OR(Progetti!E8="",Progetti!AA8=""),"",Progetti!AA8) -> 46265 | S10: =IF(OR(Progetti!E8="",Progetti!AB8=""),"",Progetti!AB8) | T10: =IF(OR(Progetti!E8="",Progetti!AC8=""),"",Progetti!AC8) | U10: =IF(OR(Progetti!E8="",Progetti!AD8=""),"",Progetti!AD8) | V10: =IF(OR(Progetti!E8="",Progetti!AE8=""),"",Progetti!AE8) | W10: =IF(OR(Progetti!E8="",Progetti!AF8=""),"",Progetti!AF8) | X10: =IF(OR(Progetti!E8="",Progetti!AG8=""),"",Progetti!AG8)
A11: =IF(Progetti!E9="","",Progetti!A9) -> Catania | B11: =IF(Progetti!F9="","",Progetti!B9) -> Sud | C11: =IF(Progetti!E9="","",Progetti!C9) -> ENGIE GRILLO SRL | D11: =IF(Progetti!F9="","",Progetti!D9) -> 0 | E11: =IF(Progetti!E9="","",Progetti!E9) -> Grillo | F11: =IF(Progetti!K9="","",Progetti!K9) | G11: =IF(Progetti!L9="","",Progetti!L9) | H11: =IF(Progetti!E9="","",Progetti!N9) -> Autorizzazioni | I11: =IF(Progetti!E9="","",Progetti!M9) -> In pipeline | J11: =IF(Progetti!E9="","",Progetti!I9) -> 54 | K11: =IF(OR(Progetti!E9="",Progetti!Q9=""),"",Progetti!Q9) | L11: =IF(OR(Progetti!E9="",Progetti!R9=""),"",Progetti!R9) -> 46110 | M11: =IF(OR(Progetti!E9="",Progetti!V9=""),"",Progetti!V9) | N11: =IF(OR(Progetti!E9="",Progetti!W9=""),"",Progetti!W9) | O11: =IF(OR(Progetti!E9="",Progetti!X9=""),"",Progetti!X9) | P11: =IF(OR(Progetti!E9="",Progetti!Y9=""),"",Progetti!Y9) | Q11: =IF(OR(Progetti!E9="",Progetti!Z9=""),"",Progetti!Z9) -> 46108 | R11: =IF(OR(Progetti!E9="",Progetti!AA9=""),"",Progetti!AA9) -> 46265 | S11: =IF(OR(Progetti!E9="",Progetti!AB9=""),"",Progetti!AB9) | T11: =IF(OR(Progetti!E9="",Progetti!AC9=""),"",Progetti!AC9) | U11: =IF(OR(Progetti!E9="",Progetti!AD9=""),"",Progetti!AD9) | V11: =IF(OR(Progetti!E9="",Progetti!AE9=""),"",Progetti!AE9) | W11: =IF(OR(Progetti!E9="",Progetti!AF9=""),"",Progetti!AF9) | X11: =IF(OR(Progetti!E9="",Progetti!AG9=""),"",Progetti!AG9)
A12: =IF(Progetti!E10="","",Progetti!A10) -> Catania | B12: =IF(Progetti!F10="","",Progetti!B10) -> Sud | C12: =IF(Progetti!E10="","",Progetti!C10) -> ARYA SOLAR SRL | D12: =IF(Progetti!F10="","",Progetti!D10) -> 0 | E12: =IF(Progetti!E10="","",Progetti!E10) -> Arya Mazara | F12: =IF(Progetti!K10="","",Progetti!K10) | G12: =IF(Progetti!L10="","",Progetti!L10) | H12: =IF(Progetti!E10="","",Progetti!N10) -> Autorizzazioni | I12: =IF(Progetti!E10="","",Progetti!M10) -> In pipeline | J12: =IF(Progetti!E10="","",Progetti!I10) -> 42.3 | K12: =IF(OR(Progetti!E10="",Progetti!Q10=""),"",Progetti!Q10) | L12: =IF(OR(Progetti!E10="",Progetti!R10=""),"",Progetti!R10) -> 46030 | M12: =IF(OR(Progetti!E10="",Progetti!V10=""),"",Progetti!V10) | N12: =IF(OR(Progetti!E10="",Progetti!W10=""),"",Progetti!W10) | O12: =IF(OR(Progetti!E10="",Progetti!X10=""),"",Progetti!X10) | P12: =IF(OR(Progetti!E10="",Progetti!Y10=""),"",Progetti!Y10) | Q12: =IF(OR(Progetti!E10="",Progetti!Z10=""),"",Progetti!Z10) -> 46030 | R12: =IF(OR(Progetti!E10="",Progetti!AA10=""),"",Progetti!AA10) -> 46203 | S12: =IF(OR(Progetti!E10="",Progetti!AB10=""),"",Progetti!AB10) | T12: =IF(OR(Progetti!E10="",Progetti!AC10=""),"",Progetti!AC10) | U12: =IF(OR(Progetti!E10="",Progetti!AD10=""),"",Progetti!AD10) | V12: =IF(OR(Progetti!E10="",Progetti!AE10=""),"",Progetti!AE10) | W12: =IF(OR(Progetti!E10="",Progetti!AF10=""),"",Progetti!AF10) | X12: =IF(OR(Progetti!E10="",Progetti!AG10=""),"",Progetti!AG10)
A13: =IF(Progetti!E11="","",Progetti!A11) -> Catania | B13: =IF(Progetti!F11="","",Progetti!B11) -> Sud | C13: =IF(Progetti!E11="","",Progetti!C11) -> PIROIDE SRL | D13: =IF(Progetti!F11="","",Progetti!D11) -> 0 | E13: =IF(Progetti!E11="","",Progetti!E11) -> Progetto Piana degli Albanesi | F13: =IF(Progetti!K11="","",Progetti!K11) | G13: =IF(Progetti!L11="","",Progetti!L11) | H13: =IF(Progetti!E11="","",Progetti!N11) -> Autorizzazioni | I13: =IF(Progetti!E11="","",Progetti!M11) -> In pipeline | J13: =IF(Progetti!E11="","",Progetti!I11) -> 85.1 | K13: =IF(OR(Progetti!E11="",Progetti!Q11=""),"",Progetti!Q11) | L13: =IF(OR(Progetti!E11="",Progetti!R11=""),"",Progetti!R11) -> 46038 | M13: =IF(OR(Progetti!E11="",Progetti!V11=""),"",Progetti!V11) | N13: =IF(OR(Progetti!E11="",Progetti!W11=""),"",Progetti!W11) | O13: =IF(OR(Progetti!E11="",Progetti!X11=""),"",Progetti!X11) | P13: =IF(OR(Progetti!E11="",Progetti!Y11=""),"",Progetti!Y11) | Q13: =IF(OR(Progetti!E11="",Progetti!Z11=""),"",Progetti!Z11) -> 46038 | R13: =IF(OR(Progetti!E11="",Progetti!AA11=""),"",Progetti!AA11) -> 46203 | S13: =IF(OR(Progetti!E11="",Progetti!AB11=""),"",Progetti!AB11) | T13: =IF(OR(Progetti!E11="",Progetti!AC11=""),"",Progetti!AC11) | U13: =IF(OR(Progetti!E11="",Progetti!AD11=""),"",Progetti!AD11) | V13: =IF(OR(Progetti!E11="",Progetti!AE11=""),"",Progetti!AE11) | W13: =IF(OR(Progetti!E11="",Progetti!AF11=""),"",Progetti!AF11) | X13: =IF(OR(Progetti!E11="",Progetti!AG11=""),"",Progetti!AG11)
A14: =IF(Progetti!E12="","",Progetti!A12) -> Catania | B14: =IF(Progetti!F12="","",Progetti!B12) -> Sud | C14: =IF(Progetti!E12="","",Progetti!C12) -> 11PIU' ENERGIA SRL | D14: =IF(Progetti!F12="","",Progetti!D12) -> 0 | E14: =IF(Progetti!E12="","",Progetti!E12) -> Favara 2 | F14: =IF(Progetti!K12="","",Progetti!K12) | G14: =IF(Progetti!L12="","",Progetti!L12) | H14: =IF(Progetti!E12="","",Progetti!N12) -> Autorizzazioni | I14: =IF(Progetti!E12="","",Progetti!M12) -> In pipeline | J14: =IF(Progetti!E12="","",Progetti!I12) -> 65.1 | K14: =IF(OR(Progetti!E12="",Progetti!Q12=""),"",Progetti!Q12) | L14: =IF(OR(Progetti!E12="",Progetti!R12=""),"",Progetti!R12) -> 46055 | M14: =IF(OR(Progetti!E12="",Progetti!V12=""),"",Progetti!V12) | N14: =IF(OR(Progetti!E12="",Progetti!W12=""),"",Progetti!W12) | O14: =IF(OR(Progetti!E12="",Progetti!X12=""),"",Progetti!X12) | P14: =IF(OR(Progetti!E12="",Progetti!Y12=""),"",Progetti!Y12) | Q14: =IF(OR(Progetti!E12="",Progetti!Z12=""),"",Progetti!Z12) -> 46055 | R14: =IF(OR(Progetti!E12="",Progetti!AA12=""),"",Progetti!AA12) -> 46234 | S14: =IF(OR(Progetti!E12="",Progetti!AB12=""),"",Progetti!AB12) | T14: =IF(OR(Progetti!E12="",Progetti!AC12=""),"",Progetti!AC12) | U14: =IF(OR(Progetti!E12="",Progetti!AD12=""),"",Progetti!AD12) | V14: =IF(OR(Progetti!E12="",Progetti!AE12=""),"",Progetti!AE12) | W14: =IF(OR(Progetti!E12="",Progetti!AF12=""),"",Progetti!AF12) | X14: =IF(OR(Progetti!E12="",Progetti!AG12=""),"",Progetti!AG12)
A15: =IF(Progetti!E13="","",Progetti!A13) -> Catania | B15: =IF(Progetti!F13="","",Progetti!B13) -> Sud | C15: =IF(Progetti!E13="","",Progetti!C13) -> NDTHREE SRL | D15: =IF(Progetti!F13="","",Progetti!D13) -> 0 | E15: =IF(Progetti!E13="","",Progetti!E13) -> Pecciapertosa | F15: =IF(Progetti!K13="","",Progetti!K13) | G15: =IF(Progetti!L13="","",Progetti!L13) | H15: =IF(Progetti!E13="","",Progetti!N13) -> Autorizzazioni | I15: =IF(Progetti!E13="","",Progetti!M13) -> In pipeline | J15: =IF(Progetti!E13="","",Progetti!I13) -> 22.57 | K15: =IF(OR(Progetti!E13="",Progetti!Q13=""),"",Progetti!Q13) | L15: =IF(OR(Progetti!E13="",Progetti!R13=""),"",Progetti!R13) -> 46078 | M15: =IF(OR(Progetti!E13="",Progetti!V13=""),"",Progetti!V13) | N15: =IF(OR(Progetti!E13="",Progetti!W13=""),"",Progetti!W13) | O15: =IF(OR(Progetti!E13="",Progetti!X13=""),"",Progetti!X13) | P15: =IF(OR(Progetti!E13="",Progetti!Y13=""),"",Progetti!Y13) | Q15: =IF(OR(Progetti!E13="",Progetti!Z13=""),"",Progetti!Z13) -> 46078 | R15: =IF(OR(Progetti!E13="",Progetti!AA13=""),"",Progetti!AA13) -> 46234 | S15: =IF(OR(Progetti!E13="",Progetti!AB13=""),"",Progetti!AB13) | T15: =IF(OR(Progetti!E13="",Progetti!AC13=""),"",Progetti!AC13) | U15: =IF(OR(Progetti!E13="",Progetti!AD13=""),"",Progetti!AD13) | V15: =IF(OR(Progetti!E13="",Progetti!AE13=""),"",Progetti!AE13) | W15: =IF(OR(Progetti!E13="",Progetti!AF13=""),"",Progetti!AF13) | X15: =IF(OR(Progetti!E13="",Progetti!AG13=""),"",Progetti!AG13)
A16: =IF(Progetti!E14="","",Progetti!A14) -> Catania | B16: =IF(Progetti!F14="","",Progetti!B14) -> Sud | C16: =IF(Progetti!E14="","",Progetti!C14) -> IBVI 5 SRL | D16: =IF(Progetti!F14="","",Progetti!D14) -> 0 | E16: =IF(Progetti!E14="","",Progetti!E14) -> Castel di Iudica II | F16: =IF(Progetti!K14="","",Progetti!K14) | G16: =IF(Progetti!L14="","",Progetti!L14) | H16: =IF(Progetti!E14="","",Progetti!N14) -> Autorizzazioni | I16: =IF(Progetti!E14="","",Progetti!M14) -> In pipeline | J16: =IF(Progetti!E14="","",Progetti!I14) -> 231.6 | K16: =IF(OR(Progetti!E14="",Progetti!Q14=""),"",Progetti!Q14) | L16: =IF(OR(Progetti!E14="",Progetti!R14=""),"",Progetti!R14) -> 45923 | M16: =IF(OR(Progetti!E14="",Progetti!V14=""),"",Progetti!V14) | N16: =IF(OR(Progetti!E14="",Progetti!W14=""),"",Progetti!W14) | O16: =IF(OR(Progetti!E14="",Progetti!X14=""),"",Progetti!X14) | P16: =IF(OR(Progetti!E14="",Progetti!Y14=""),"",Progetti!Y14) | Q16: =IF(OR(Progetti!E14="",Progetti!Z14=""),"",Progetti!Z14) -> 45923 | R16: =IF(OR(Progetti!E14="",Progetti!AA14=""),"",Progetti!AA14) -> 46142 | S16: =IF(OR(Progetti!E14="",Progetti!AB14=""),"",Progetti!AB14) | T16: =IF(OR(Progetti!E14="",Progetti!AC14=""),"",Progetti!AC14) | U16: =IF(OR(Progetti!E14="",Progetti!AD14=""),"",Progetti!AD14) | V16: =IF(OR(Progetti!E14="",Progetti!AE14=""),"",Progetti!AE14) | W16: =IF(OR(Progetti!E14="",Progetti!AF14=""),"",Progetti!AF14) | X16: =IF(OR(Progetti!E14="",Progetti!AG14=""),"",Progetti!AG14)
A17: =IF(Progetti!E15="","",Progetti!A15) -> Catania | B17: =IF(Progetti!F15="","",Progetti!B15) -> Sud | C17: =IF(Progetti!E15="","",Progetti!C15) -> IBVI 22 SRL | D17: =IF(Progetti!F15="","",Progetti!D15) -> 0 | E17: =IF(Progetti!E15="","",Progetti!E15) -> Mineo | F17: =IF(Progetti!K15="","",Progetti!K15) | G17: =IF(Progetti!L15="","",Progetti!L15) | H17: =IF(Progetti!E15="","",Progetti!N15) -> Autorizzazioni | I17: =IF(Progetti!E15="","",Progetti!M15) -> In pipeline | J17: =IF(Progetti!E15="","",Progetti!I15) -> 263 | K17: =IF(OR(Progetti!E15="",Progetti!Q15=""),"",Progetti!Q15) | L17: =IF(OR(Progetti!E15="",Progetti!R15=""),"",Progetti!R15) -> 46092 | M17: =IF(OR(Progetti!E15="",Progetti!V15=""),"",Progetti!V15) | N17: =IF(OR(Progetti!E15="",Progetti!W15=""),"",Progetti!W15) | O17: =IF(OR(Progetti!E15="",Progetti!X15=""),"",Progetti!X15) | P17: =IF(OR(Progetti!E15="",Progetti!Y15=""),"",Progetti!Y15) | Q17: =IF(OR(Progetti!E15="",Progetti!Z15=""),"",Progetti!Z15) -> 46092 | R17: =IF(OR(Progetti!E15="",Progetti!AA15=""),"",Progetti!AA15) -> 46265 | S17: =IF(OR(Progetti!E15="",Progetti!AB15=""),"",Progetti!AB15) | T17: =IF(OR(Progetti!E15="",Progetti!AC15=""),"",Progetti!AC15) | U17: =IF(OR(Progetti!E15="",Progetti!AD15=""),"",Progetti!AD15) | V17: =IF(OR(Progetti!E15="",Progetti!AE15=""),"",Progetti!AE15) | W17: =IF(OR(Progetti!E15="",Progetti!AF15=""),"",Progetti!AF15) | X17: =IF(OR(Progetti!E15="",Progetti!AG15=""),"",Progetti!AG15)
A18: =IF(Progetti!E16="","",Progetti!A16) -> Catania | B18: =IF(Progetti!F16="","",Progetti!B16) -> Sud | C18: =IF(Progetti!E16="","",Progetti!C16) -> ENNA 1 PV SRL | D18: =IF(Progetti!F16="","",Progetti!D16) -> 0 | E18: =IF(Progetti!E16="","",Progetti!E16) -> Enna 1 | F18: =IF(Progetti!K16="","",Progetti!K16) | G18: =IF(Progetti!L16="","",Progetti!L16) | H18: =IF(Progetti!E16="","",Progetti!N16) -> Autorizzazioni | I18: =IF(Progetti!E16="","",Progetti!M16) -> In pipeline | J18: =IF(Progetti!E16="","",Progetti!I16) -> 45 | K18: =IF(OR(Progetti!E16="",Progetti!Q16=""),"",Progetti!Q16) | L18: =IF(OR(Progetti!E16="",Progetti!R16=""),"",Progetti!R16) -> 46086 | M18: =IF(OR(Progetti!E16="",Progetti!V16=""),"",Progetti!V16) | N18: =IF(OR(Progetti!E16="",Progetti!W16=""),"",Progetti!W16) | O18: =IF(OR(Progetti!E16="",Progetti!X16=""),"",Progetti!X16) | P18: =IF(OR(Progetti!E16="",Progetti!Y16=""),"",Progetti!Y16) | Q18: =IF(OR(Progetti!E16="",Progetti!Z16=""),"",Progetti!Z16) -> 46086 | R18: =IF(OR(Progetti!E16="",Progetti!AA16=""),"",Progetti!AA16) -> 46265 | S18: =IF(OR(Progetti!E16="",Progetti!AB16=""),"",Progetti!AB16) | T18: =IF(OR(Progetti!E16="",Progetti!AC16=""),"",Progetti!AC16) | U18: =IF(OR(Progetti!E16="",Progetti!AD16=""),"",Progetti!AD16) | V18: =IF(OR(Progetti!E16="",Progetti!AE16=""),"",Progetti!AE16) | W18: =IF(OR(Progetti!E16="",Progetti!AF16=""),"",Progetti!AF16) | X18: =IF(OR(Progetti!E16="",Progetti!AG16=""),"",Progetti!AG16)
... A206: =IF(Progetti!E204="","",Progetti!A204) | B206: =IF(Progetti!F204="","",Progetti!B204) | C206: =IF(Progetti!E204="","",Progetti!C204) | D206: =IF(Progetti!F204="","",Progetti!D204) | E206: =IF(Progetti!E204="","",Progetti!E204) | F206: =IF(Progetti!K204="","",Progetti!K204) | G206: =IF(Progetti!L204="","",Progetti!L204) | H206: =IF(Progetti!E204="","",Progetti!N204) | I206: =IF(Progetti!E204="","",Progetti!M204) | J206: =IF(Progetti!E204="","",Progetti!I204) | K206: =IF(OR(Progetti!E204="",Progetti!Q204=""),"",Progetti!Q204) | L206: =IF(OR(Progetti!E204="",Progetti!R204=""),"",Progetti!R204) | M206: =IF(OR(Progetti!E204="",Progetti!V204=""),"",Progetti!V204) | N206: =IF(OR(Progetti!E204="",Progetti!W204=""),"",Progetti!W204) | O206: =IF(OR(Progetti!E204="",Progetti!X204=""),"",Progetti!X204) | P206: =IF(OR(Progetti!E204="",Progetti!Y204=""),"",Progetti!Y204) | Q206: =IF(OR(Progetti!E204="",Progetti!Z204=""),"",Progetti!Z204) | R206: =IF(OR(Progetti!E204="",Progetti!AA204=""),"",Progetti!AA204) | S206: =IF(OR(Progetti!E204="",Progetti!AB204=""),"",Progetti!AB204) | T206: =IF(OR(Progetti!E204="",Progetti!AC204=""),"",Progetti!AC204) | U206: =IF(OR(Progetti!E204="",Progetti!AD204=""),"",Progetti!AD204) | V206: =IF(OR(Progetti!E204="",Progetti!AE204=""),"",Progetti!AE204) | W206: =IF(OR(Progetti!E204="",Progetti!AF204=""),"",Progetti!AF204) | X206: =IF(OR(Progetti!E204="",Progetti!AG204=""),"",Progetti!AG204)

Sheet GeoListe
A1: Regioni | B1: Abruzzo | C1: Basilicata | D1: Calabria | E1: Campania | F1: Emilia-Romagna | G1: Friuli-Venezia Giulia | H1: Lazio | I1: Liguria | J1: Lombardia | K1: Marche | L1: Molise | M1: Piemonte | N1: Puglia | O1: Sardegna | P1: Sicilia | Q1: Toscana | R1: Trentino-Alto Adige/Südtirol | S1: Umbria | T1: Valle d'Aosta/Vallée d'Aoste | U1: Veneto
A2: Abruzzo | B2: Chieti | C2: Matera | D2: Catanzaro | E2: Avellino | F2: Bologna | G2: Gorizia | H2: Frosinone | I2: Genova | J2: Bergamo | K2: Ancona | L2: Campobasso | M2: Alessandria | N2: Bari | O2: Cagliari | P2: Agrigento | Q2: Arezzo | R2: Bolzano/Bozen | S2: Perugia | T2: Valle d'Aosta/Vallée d'Aoste | U2: Belluno
A3: Basilicata | B3: L'Aquila | C3: Potenza | D3: Cosenza | E3: Benevento | F3: Ferrara | G3: Pordenone | H3: Latina | I3: Imperia | J3: Brescia | K3: Ascoli Piceno | L3: Isernia | M3: Asti | N3: Barletta-Andria-Trani | O3: Nuoro | P3: Caltanissetta | Q3: Firenze | R3: Trento | S3: Terni | U3: Padova
A4: Calabria | B4: Pescara | D4: Crotone | E4: Caserta | F4: Forlì-Cesena | G4: Trieste | H4: Rieti | I4: La Spezia | J4: Como | K4: Fermo | M4: Biella | N4: Brindisi | O4: Oristano | P4: Catania | Q4: Grosseto | U4: Rovigo
A5: Campania | B5: Teramo | D5: Reggio Calabria | E5: Napoli | F5: Modena | G5: Udine | H5: Roma | I5: Savona | J5: Cremona | K5: Macerata | M5: Cuneo | N5: Foggia | O5: Sassari | P5: Enna | Q5: Livorno | U5: Treviso
A6: Emilia-Romagna | D6: Vibo Valentia | E6: Salerno | F6: Parma | H6: Viterbo | J6: Lecco | K6: Pesaro e Urbino | M6: Novara | N6: Lecce | O6: Sud Sardegna | P6: Messina | Q6: Lucca | U6: Venezia
A7: Friuli-Venezia Giulia | F7: Piacenza | J7: Lodi | M7: Torino | N7: Taranto | P7: Palermo | Q7: Massa-Carrara | U7: Verona
A8: Lazio | F8: Ravenna | J8: Mantova | M8: Verbano-Cusio-Ossola | P8: Ragusa | Q8: Pisa | U8: Vicenza
A9: Liguria | F9: Reggio nell'Emilia | J9: Milano | M9: Vercelli | P9: Siracusa | Q9: Pistoia
A10: Lombardia | F10: Rimini | J10: Monza e della Brianza | P10: Trapani | Q10: Prato
A11: Marche | J11: Pavia | Q11: Siena
A12: Molise | J12: Sondrio
A13: Piemonte | J13: Varese
A14: Puglia
A15: Sardegna
A16: Sicilia
A17: Toscana
A18: Trentino-Alto Adige/Südtirol
A19: Umbria
A20: Valle d'Aosta/Vallée d'Aoste
A21: Veneto

Sheet GeoComuni
A1: Regione | B1: Provincia | C1: Comune | E1: Fonte
A2: Abruzzo | B2: Chieti | C2: Altino | E2: https://www.istat.it/storage/codici-unita-amministrative/Elenco-comuni-italiani.csv
A3: Abruzzo | B3: Chieti | C3: Archi | E3: Scaricato il 2026-03-15
A4: Abruzzo | B4: Chieti | C4: Ari
A5: Abruzzo | B5: Chieti | C5: Arielli
A6: Abruzzo | B6: Chieti | C6: Atessa
A7: Abruzzo | B7: Chieti | C7: Bomba
A8: Abruzzo | B8: Chieti | C8: Borrello
A9: Abruzzo | B9: Chieti | C9: Bucchianico
A10: Abruzzo | B10: Chieti | C10: Canosa Sannita
A11: Abruzzo | B11: Chieti | C11: Carpineto Sinello
A12: Abruzzo | B12: Chieti | C12: Carunchio
A13: Abruzzo | B13: Chieti | C13: Casacanditella
A14: Abruzzo | B14: Chieti | C14: Casalanguida
A15: Abruzzo | B15: Chieti | C15: Casalbordino
... A7896: Veneto | B7896: Vicenza | C7896: Zugliano

Sheet GeoDropdown
A1: Agrigento | B1: Alessandria | C1: Ancona | D1: Arezzo | E1: Ascoli Piceno | F1: Asti | G1: Avellino | H1: Bari | I1: Barletta-Andria-Trani | J1: Belluno | K1: Benevento | L1: Bergamo | M1: Biella | N1: Bologna | O1: Bolzano/Bozen | P1: Brescia | Q1: Brindisi | R1: Cagliari | S1: Caltanissetta | T1: Campobasso | U1: Caserta | V1: Catania | W1: Catanzaro | X1: Chieti | Y1: Como | Z1: Cosenza | AA1: Cremona | AB1: Crotone | AC1: Cuneo | AD1: Enna | AE1: Fermo | AF1: Ferrara | AG1: Firenze | AH1: Foggia | AI1: Forlì-Cesena | AJ1: Frosinone | AK1: Genova | AL1: Gorizia | AM1: Grosseto | AN1: Imperia | AO1: Isernia | AP1: L'Aquila | AQ1: La Spezia | AR1: Latina | AS1: Lecce | AT1: Lecco | AU1: Livorno | AV1: Lodi | AW1: Lucca | AX1: Macerata | AY1: Mantova | AZ1: Massa-Carrara | BA1: Matera | BB1: Messina | BC1: Milano | BD1: Modena | BE1: Monza e della Brianza | BF1: Napoli | BG1: Novara | BH1: Nuoro | BI1: Oristano | BJ1: Padova | BK1: Palermo | BL1: Parma | BM1: Pavia | BN1: Perugia | BO1: Pesaro e Urbino | BP1: Pescara | BQ1: Piacenza | BR1: Pisa | BS1: Pistoia | BT1: Pordenone | BU1: Potenza | BV1: Prato | BW1: Ragusa | BX1: Ravenna | BY1: Reggio Calabria | BZ1: Reggio nell'Emilia | CA1: Rieti | CB1: Rimini | CC1: Roma | CD1: Rovigo | CE1: Salerno | CF1: Sassari | CG1: Savona | CH1: Siena | CI1: Siracusa | CJ1: Sondrio | CK1: Sud Sardegna | CL1: Taranto | CM1: Teramo | CN1: Terni | CO1: Torino | CP1: Trapani | CQ1: Trento | CR1: Treviso | CS1: Trieste | CT1: Udine | CU1: Valle d'Aosta/Vallée d'Aoste | CV1: Varese | CW1: Venezia | CX1: Verbano-Cusio-Ossola | CY1: Vercelli | CZ1: Verona | DA1: Vibo Valentia | DB1: Vicenza | DC1: Viterbo
A2: Agrigento | B2: Acqui Terme | C2: Agugliano | D2: Anghiari | E2: Acquasanta Terme | F2: Agliano Terme | G2: Aiello del Sabato | H2: Acquaviva delle Fonti | I2: Andria | J2: Agordo | K2: Airola | L2: Adrara San Martino | M2: Ailoche | N2: Alto Reno Terme | O2: Aldino/Aldein | P2: Acquafredda | Q2: Brindisi | R2: Assemini | S2: Acquaviva Platani | T2: Acquaviva Collecroce | U2: Ailano | V2: Aci Bonaccorsi | W2: Albi | X2: Altino | Y2: Albavilla | Z2: Acquaformosa | AA2: Acquanegra Cremonese | AB2: Belvedere di Spinello | AC2: Acceglio | AD2: Agira | AE2: Altidona | AF2: Argenta | AG2: Bagno a Ripoli | AH2: Accadia | AI2: Bagno di Romagna | AJ2: Acquafondata | AK2: Arenzano | AL2: Capriva del Friuli | AM2: Arcidosso | AN2: Airole | AO2: Acquaviva d'Isernia | AP2: Acciano | AQ2: Ameglia | AR2: Aprilia | AS2: Alessano | AT2: Abbadia Lariana | AU2: Bibbona | AV2: Abbadia Cerreto | AW2: Altopascio | AX2: Apiro | AY2: Acquanegra sul Chiese | AZ2: Aulla | BA2: Accettura | BB2: Acquedolci | BC2: Abbiategrasso | BD2: Bastiglia | BE2: Agrate Brianza | BF2: Acerra | BG2: Agrate Conturbia | BH2: Aritzo | BI2: Abbasanta | BJ2: Abano Terme | BK2: Alia | BL2: Albareto | BM2: Alagna | BN2: Assisi | BO2: Acqualagna | BP2: Abbateggio | BQ2: Agazzano | BR2: Bientina | BS2: Abetone Cutigliano | BT2: Andreis | BU2: Abriola | BV2: Cantagallo | BW2: Acate | BX2: Alfonsine | BY2: Africo | BZ2: Albinea | CA2: Accumoli | CB2: Bellaria-Igea Marina | CC2: Affile | CD2: Adria | CE2: Acerno | CF2: Aggius | CG2: Alassio | CH2: Abbadia San Salvatore | CI2: Augusta | CJ2: Albaredo per San Marco | CK2: Arbus | CL2: Avetrana | CM2: Alba Adriatica | CN2: Acquasparta | CO2: Agliè | CP2: Alcamo | CQ2: Ala | CR2: Altivole | CS2: Duino Aurisina-Devin Nabreina | CT2: Aiello del Friuli | CU2: Allein | CV2: Agra | CW2: Annone Veneto | CX2: Antrona Schieranco | CY2: Alagna Valsesia | CZ2: Affi | DA2: Acquaro | DB2: Agugliaro | DC2: Acquapendente
A3: Alessandria della Rocca | B3: Albera Ligure | C3: Ancona | D3: Arezzo | E3: Acquaviva Picena | F3: Albugnano | G3: Altavilla Irpina | H3: Adelfia | I3: Barletta | J3: Alleghe | K3: Amorosi | L3: Adrara San Rocco | M3: Andorno Micca | N3: Anzola dell'Emilia | O3: Andriano/Andrian | P3: Adro | Q3: Carovigno | R3: Cagliari | S3: Bompensiere | T3: Baranello | U3: Alife | V3: Aci Castello | W3: Amaroni | X3: Archi | Y3: Albese con Cassano | Z3: Acquappesa | AA3: Agnadello | AB3: Caccuri | AC3: Aisone | AD3: Aidone | AE3: Amandola | AF3: Bondeno | AG3: Barberino Tavarnelle | AH3: Alberona | AI3: Bertinoro | AJ3: Acuto | AK3: Avegno | AL3: Cormons | AM3: Campagnatico | AN3: Apricale | AO3: Agnone | AP3: Aielli | AQ3: Arcola | AR3: Bassiano | AS3: Alezio | AT3: Airuno | AU3: Campiglia Marittima | AV3: Bertonico | AW3: Bagni di Lucca | AX3: Appignano | AY3: Asola | AZ3: Bagnone | BA3: Aliano | BB3: Alcara li Fusi | BC3: Albairate | BD3: Bomporto | BE3: Aicurzio | BF3: Afragola | BG3: Ameno | BH3: Arzana | BI3: Aidomaggiore | BJ3: Agna | BK3: Alimena | BL3: Bardi | BM3: Albonese | BN3: Bastia Umbra | BO3: Apecchio | BP3: Alanno | BQ3: Alseno | BR3: Buti | BS3: Agliana | BT3: Arba | BU3: Acerenza | BV3: Carmignano | BW3: Chiaramonte Gulfi | BX3: Bagnacavallo | BY3: Agnana Calabra | BZ3: Bagnolo in Piano | CA3: Amatrice | CB3: Casteldelci | CC3: Agosta | CD3: Ariano nel Polesine | CE3: Agropoli | CF3: Aglientu | CG3: Albenga | CH3: Asciano | CI3: Avola | CJ3: Albosaggia | CK3: Armungia | CL3: Carosino | CM3: Ancarano | CN3: Allerona | CO3: Airasca | CP3: Buseto Palizzolo | CQ3: Albiano | CR3: Arcade | CS3: Monrupino-Repentabor | CT3: Amaro | CU3: Antey-Saint-André | CV3: Albizzate | CW3: Campagna Lupia | CX3: Anzola d'Ossola | CY3: Albano Vercellese | CZ3: Albaredo d'Adige | DA3: Arena | DB3: Albettone | DC3: Arlena di Castro
A4: Aragona | B4: Alessandria | C4: Arcevia | D4: Badia Tedalda | E4: Appignano del Tronto | F4: Antignano | G4: Andretta | H4: Alberobello | I4: Bisceglie | J4: Alpago | K4: Apice | L4: Albano Sant'Alessandro | M4: Benna | N4: Argelato | O4: Anterivo/Altrei | P4: Agnosine | Q4: Ceglie Messapica | R4: Capoterra | S4: Butera | T4: Bojano | U4: Alvignano | V4: Aci Catena | W4: Amato | X4: Ari | Y4: Albiolo | Z4: Acri | AA4: Annicco | AB4: Carfizzi | AC4: Alba | AD4: Assoro | AE4: Belmonte Piceno | AF4: Cento | AG4: Barberino di Mugello | AH4: Anzano di Puglia | AI4: Borghi | AJ4: Alatri | AK4: Bargagli | AL4: Doberdò del Lago-Doberdob | AM4: Capalbio | AN4: Aquila d'Arroscia | AO4: Bagnoli del Trigno | AP4: Alfedena | AQ4: Beverino | AR4: Campodimele | AS4: Alliste | AT4: Annone di Brianza | AU4: Campo nell'Elba | AV4: Boffalora d'Adda | AW4: Barga | AX4: Belforte del Chienti | AY4: Bagnolo San Vito | AZ4: Carrara | BA4: Bernalda | BB4: Alì | BC4: Arconate | BD4: Campogalliano | BE4: Albiate | BF4: Agerola | BG4: Armeno | BH4: Atzara | BI4: Albagiara | BJ4: Albignasego | BK4: Aliminusa | BL4: Bedonia | BM4: Albuzzano | BN4: Bettona | BO4: Belforte all'Isauro | BP4: Bolognano | BQ4: Alta Val Tidone | BR4: Calci | BS4: Buggiano | BT4: Aviano | BU4: Albano di Lucania | BV4: Montemurlo | BW4: Comiso | BX4: Bagnara di Romagna | BY4: Anoia | BZ4: Baiso | CA4: Antrodoco | CB4: Cattolica | CC4: Albano Laziale | CD4: Arquà Polesine | CE4: Albanella | CF4: Alghero | CG4: Albisola Superiore | CH4: Buonconvento | CI4: Buccheri | CJ4: Andalo Valtellino | CK4: Ballao | CL4: Castellaneta | CM4: Arsita | CN4: Alviano | CO4: Ala di Stura | CP4: Calatafimi-Segesta | CQ4: Aldeno | CR4: Asolo | CS4: Muggia | CT4: Ampezzo | CU4: Aosta | CV4: Angera | CW4: Campolongo Maggiore | CX4: Arizzano | CY4: Alice Castello | CZ4: Angiari | DA4: Briatico | DB4: Alonte | DC4: Bagnoregio
A5: Bivona | B5: Alfiano Natta | C5: Barbara | D5: Bibbiena | E5: Arquata del Tronto | F5: Aramengo | G5: Aquilonia | H5: Altamura | I5: Canosa di Puglia | J5: Arsiè | K5: Apollosa | L5: Albino | M5: Biella | N5: Baricella | O5: Appiano sulla strada del vino/Eppan an der Weinstraße | P5: Alfianello | Q5: Cellino San Marco | R5: Decimomannu | S5: Caltanissetta | T5: Bonefro | U5: Arienzo | V5: Aci Sant'Antonio | W5: Andali | X5: Arielli | Y5: Alserio | Z5: Aiello Calabro | AA5: Azzanello | AB5: Casabona | AC5: Albaretto della Torre | AD5: Barrafranca | AE5: Campofilone | AF5: Codigoro | AG5: Borgo San Lorenzo | AH5: Apricena | AI5: Castrocaro Terme e Terra del Sole | AJ5: Alvito | AK5: Bogliasco | AL5: Dolegna del Collio | AM5: Castel del Piano | AN5: Armo | AO5: Belmonte del Sannio | AP5: Anversa degli Abruzzi | AQ5: Bolano | AR5: Castelforte | AS5: Andrano | AT5: Ballabio | AU5: Capoliveri | AV5: Borghetto Lodigiano | AW5: Borgo a Mozzano | AX5: Bolognola | AY5: Borgo Mantovano | AZ5: Casola in Lunigiana | BA5: Calciano | BB5: Alì Terme | BC5: Arese | BD5: Camposanto | BE5: Arcore | BF5: Anacapri | BG5: Arona | BH5: Austis | BI5: Ales | BJ5: Anguillara Veneta | BK5: Altavilla Milicia | BL5: Berceto | BM5: Arena Po | BN5: Bevagna | BO5: Borgo Pace | BP5: Brittoli | BQ5: Besenzone | BR5: Calcinaia | BS5: Chiesina Uzzanese | BT5: Azzano Decimo | BU5: Anzi | BV5: Poggio a Caiano | BW5: Giarratana | BX5: Brisighella | BY5: Antonimina | BZ5: Bibbiano | CA5: Ascrea | CB5: Coriano | CC5: Allumiere | CD5: Badia Polesine | CE5: Alfano | CF5: Alà dei Sardi | CG5: Albissola Marina | CH5: Casole d'Elsa | CI5: Buscemi | CJ5: Aprica | CK5: Barrali | CL5: Crispiano | CM5: Atri | CN5: Amelia | CO5: Albiano d'Ivrea | CP5: Campobello di Mazara | CQ5: Altavalle | CR5: Borso del Grappa | CS5: San Dorligo della Valle-Dolina | CT5: Aquileia | CU5: Arnad | CV5: Arcisate | CW5: Camponogara | CX5: Arola | CY5: Alto Sermenza | CZ5: Arcole | DA5: Brognaturo | DB5: Altavilla Vicentina | DC5: Barbarano Romano
A6: Burgio | B6: Alice Bel Colle | C6: Belvedere Ostrense | D6: Bucine | E6: Ascoli Piceno | F6: Asti | G6: Ariano Irpino | H6: Bari | I6: Margherita di Savoia | J6: Auronzo di Cadore | K6: Arpaia | L6: Algua | M6: Bioglio | N6: Bentivoglio | O6: Avelengo/Hafling | P6: Anfo | Q6: Cisternino | R6: Elmas | S6: Campofranco | T6: Busso | U6: Aversa | V6: Acireale | W6: Argusto | X6: Atessa | Y6: Alta Valle Intelvi | Z6: Aieta | AA6: Bagnolo Cremasco | AB6: Castelsilano | AC6: Alto | AD6: Calascibetta | AE6: Falerone | AF6: Comacchio | AG6: Calenzano | AH6: Ascoli Satriano | AI6: Cesena | AJ6: Amaseno | AK6: Borzonasca | AL6: Farra d'Isonzo | AM6: Castell'Azzara | AN6: Aurigo | AO6: Cantalupo nel Sannio | AP6: Ateleta | AQ6: Bonassola | AR6: Cisterna di Latina | AS6: Aradeo | AT6: Barzago | AU6: Capraia Isola | AV6: Borgo San Giovanni | AW6: Camaiore | AX6: Caldarola | AY6: Borgo Virgilio | AZ6: Comano | BA6: Cirigliano | BB6: Antillo | BC6: Arluno | BD6: Carpi | BE6: Barlassina | BF6: Arzano | BG6: Barengo | BH6: Bari Sardo | BI6: Allai | BJ6: Arquà Petrarca | BK6: Altofonte | BL6: Bore | BM6: Badia Pavese | BN6: Campello sul Clitunno | BO6: Cagli | BP6: Bussi sul Tirino | BQ6: Bettola | BR6: Capannoli | BS6: Lamporecchio | BT6: Barcis | BU6: Armento | BV6: Prato | BW6: Ispica | BX6: Casola Valsenio | BY6: Ardore | BZ6: Boretto | CA6: Belmonte in Sabina | CB6: Gemmano | CC6: Anguillara Sabazia | CD6: Bagnolo di Po | CE6: Altavilla Silentina | CF6: Anela | CG6: Altare | CH6: Castellina in Chianti | CI6: Canicattini Bagni | CJ6: Ardenno | CK6: Barumini | CL6: Faggiano | CM6: Basciano | CN6: Arrone | CO6: Almese | CP6: Castellammare del Golfo | CQ6: Altopiano della Vigolana | CR6: Breda di Piave | CS6: Sgonico-Zgonik | CT6: Arta Terme | CU6: Arvier | CV6: Arsago Seprio | CW6: Caorle | CX6: Aurano | CY6: Arborio | CZ6: Badia Calavena | DA6: Capistrano | DB6: Altissimo | DC6: Bassano Romano
A7: Calamonaci | B7: Alluvioni Piovera | C7: Camerano | D7: Capolona | E7: Carassai | F7: Azzano d'Asti | G7: Atripalda | H7: Binetto | I7: Minervino Murge | J7: Belluno | K7: Arpaise | L7: Almenno San Bartolomeo | M7: Borriana | N7: Bologna | O7: Badia/Abtei | P7: Angolo Terme | Q7: Erchie | R7: Maracalagonis | S7: Delia | T7: Campobasso | U7: Baia e Latina | V7: Adrano | W7: Badolato | X7: Bomba | Y7: Alzate Brianza | Z7: Albidona | AA7: Bonemerse | AB7: Cerenzia | AC7: Argentera | AD7: Catenanuova | AE7: Fermo | AF7: Copparo | AG7: Campi Bisenzio | AH7: Biccari | AI7: Cesenatico | AJ7: Anagni | AK7: Busalla | AL7: Fogliano Redipuglia | AM7: Castiglione della Pescaia | AN7: Badalucco | AO7: Capracotta | AP7: Avezzano | AQ7: Borghetto di Vara | AR7: Cori | AS7: Arnesano | AT7: Barzanò | AU7: Castagneto Carducci | AV7: Brembio | AW7: Camporgiano | AX7: Camerino | AY7: Borgocarbonara | AZ7: Filattiera | BA7: Colobraro | BB7: Barcellona Pozzo di Gotto | BC7: Assago | BD7: Castelfranco Emilia | BE7: Bellusco | BF7: Bacoli | BG7: Bellinzago Novarese | BH7: Baunei | BI7: Arborea | BJ7: Arre | BK7: Bagheria | BL7: Borgo Val di Taro | BM7: Bagnaria | BN7: Cannara | BO7: Cantiano | BP7: Cappelle sul Tavo | BQ7: Bobbio | BR7: Casale Marittimo | BS7: Larciano | BT7: Brugnera | BU7: Atella | BV7: Vaiano | BW7: Modica | BX7: Castel Bolognese | BY7: Bagaladi | BZ7: Brescello | CA7: Borbona | CB7: Maiolo | CC7: Anticoli Corrado | CD7: Bergantino | CE7: Amalfi | CF7: Ardara | CG7: Andora | CH7: Castelnuovo Berardenga | CI7: Carlentini | CJ7: Bema | CK7: Buggerru | CL7: Fragagnano | CM7: Bellante | CN7: Attigliano | CO7: Alpette | CP7: Castelvetrano | CQ7: Amblar-Don | CR7: Caerano di San Marco | CS7: Trieste | CT7: Artegna | CU7: Avise | CV7: Azzate | CW7: Cavallino-Treporti | CX7: Baceno | CY7: Asigliano Vercellese | CZ7: Bardolino | DA7: Cessaniti | DB7: Arcugnano | DC7: Bassano in Teverina
A8: Caltabellotta | B8: Altavilla Monferrato | C8: Camerata Picena | D8: Caprese Michelangelo | E8: Castel di Lama | F8: Baldichieri d'Asti | G8: Avella | H8: Bitetto | I8: San Ferdinando di Puglia | J8: Borca di Cadore | K8: Baselice | L8: Almenno San Salvatore | M8: Brusnengo | N8: Borgo Tossignano | O8: Barbiano/Barbian | P8: Artogne | Q8: Fasano | R8: Monserrato | S8: Gela | T8: Campochiaro | U8: Bellona | V8: Belpasso | W8: Belcastro | X8: Borrello | Y8: Anzano del Parco | Z8: Alessandria del Carretto | AA8: Bordolano | AB8: Cirò | AC8: Arguello | AD8: Centuripe | AE8: Francavilla d'Ete | AF8: Ferrara | AG8: Capraia e Limite | AH8: Bovino | AI8: Civitella di Romagna | AJ8: Aquino | AK8: Camogli | AL8: Gorizia | AM8: Cinigiano | AN8: Bajardo | AO8: Carovilli | AP8: Balsorano | AQ8: Brugnato | AR8: Fondi | AS8: Bagnolo del Salento | AT8: Barzio | AU8: Cecina | AV8: Casaletto Lodigiano | AW8: Capannori | AX8: Camporotondo di Fiastrone | AY8: Bozzolo | AZ8: Fivizzano | BA8: Craco | BB8: Basicò | BC8: Baranzate | BD8: Castelnuovo Rangone | BE8: Bernareggio | BF8: Barano d'Ischia | BG8: Biandrate | BH8: Belvì | BI8: Ardauli | BJ8: Arzergrande | BK8: Balestrate | BL8: Busseto | BM8: Barbianello | BN8: Cascia | BO8: Carpegna | BP8: Caramanico Terme | BQ8: Borgonovo Val Tidone | BR8: Casciana Terme Lari | BS8: Marliana | BT8: Budoia | BU8: Avigliano | BV8: Vernio | BW8: Monterosso Almo | BX8: Cervia | BY8: Bagnara Calabra | BZ8: Cadelbosco di Sopra | CA8: Borgo Velino | CB8: Misano Adriatico | CC8: Anzio | CD8: Bosaro | CE8: Angri | CF8: Arzachena | CG8: Arnasco | CH8: Castiglione d'Orcia | CI8: Cassaro | CJ8: Berbenno di Valtellina | CK8: Burcei | CL8: Ginosa | CM8: Bisenti | CN8: Avigliano Umbro | CO8: Alpignano | CP8: Custonaci | CQ8: Andalo | CR8: Cappella Maggiore | CT8: Attimis | CU8: Ayas | CV8: Azzio | CW8: Cavarzere | CX8: Bannio Anzino | CY8: Balmuccia | CZ8: Belfiore | DA8: Dasà | DB8: Arsiero | DC8: Blera
